Workbook

Sheet 안내
A1: 보조지표 사전 매칭 누락 검수 — 저자 판정 시트 (옵션 판정판)
A3: 무엇을 보는가
A4: 광고·미디어·지역 시트의 문장은 그 지수의 사전에 '잡히지 않은' 불릿 중 무작위 200건이다(seed 0). '모델 판독'은 Claude가 읽고 적은 Y(잡혔어야 함)/N. 노란 행이 Y다.
A6: 행마다 고르는 판정 옵션 (열 H, 드롭다운)
A7: A 누락·사전추가 — 이 지표에 잡혔어야 하고, 열 I '추가할 표현'에 문장에 나온 말 그대로(예: Seoul, 런닝맨, brand ambassador)를 적고, 열 J '집계 대상'에 그 말이 셀 곳을 고른다. 지역은 시·도(Seoul → 서울, 봉화 → 경북), 미디어는 서브태그(런닝맨 → 예능). 광고는 신호 목록 하나라 집계 대상이 없다.
A8: B 누락·사전제외 — 잡혔어야 하지만 표현이 일회성·고유명이라 사전에는 넣지 않는다. 누락으로만 집계한다(재현율 추정에 반영).
A9: C 경계·정의결정 — 지표 정의를 넓히면 포함되는 사례. 예: 라디오 출연을 '미디어 노출'로 볼지, 영문 지명을 '국내 지역 언급'으로 볼지. 정의결정 시트의 답에 따라 자동으로 A 또는 D로 취급한다.
A10: D 아님 — 지표 대상이 아니다. 사전이 맞게 안 잡은 것.
A11: E 보류 — 판단 유보. 집계에서는 누락 아님으로 센다.
A13: 정의결정 시트
A14: 표본을 읽다 보면 개별 문장보다 '이 지표가 무엇을 재는가'를 정해야 하는 질문이 반복된다. 그 질문 12개를 모아 선택지와 영향을 적었다. 여기 답이 C 판정의 처리와 사전 후보의 채택 범위를 정한다. 권장안은 참고일 뿐이다.
A16: 사전후보 시트
... A23: 이 파일을 같은 이름으로 채워 주면 --summarize-xlsx 로 집계하고, A로 확정된 표현과 채택된 후보를 사전 CSV에 넣어 보조지표를 재산출한다. 정의결정 시트의 답은 그 재산출 규칙이 된다.

Sheet 정의결정
A1: 지표 | B1: 결정 질문 | C1: 선택지 | D1: 선택 시 영향 | E1: 권장(참고) | F1: 저자 선택 | G1: 메모
A2: 광고 | B2: Q1 영문 불릿의 상업 계약 신호(brand ambassador, endorsement, brand model, spokesmodel, promotional face)를 사전에 넣는가 | C2: · 넣는다(영문 신호 추가) · 넣지 않는다(한국어 근거만 집계) · 보류 | D2: 표본에서 광고 누락 7건 중 6건이 영문 불릿. 넣으면 광고 불릿 약 +150∼300건(재현율 0.81→0.9대), 영문 근거가 많은 글로벌 팬덤(BTS·BLACKPINK·TWS·aespa 등)의 광고 지수가 오른다. | E2: 넣는다 — 지수 정의(상업 계약 신호)와 같고 언어만 다르므로
A3: 광고 | B3: Q2 '화보 공개·화보 촬영·매거진 커버'를 상업 신호로 보는가(현재 '화보 촬영'만) | C3: · 브랜드와 함께한 화보만 포함 · 화보 전부 포함 · 화보 제외(현행 유지: '화보 촬영'만) | D3: 패션·뷰티 브랜드 화보는 사실상 광고 계약이지만 잡지 표지·컴백 화보는 홍보 활동이다. '브랜드+화보'만 넣으면 소수(표본 1건), 전부 넣으면 미디어 노출과 겹친다. | E3: 브랜드와 함께한 화보만 포함
A4: 광고 | B4: Q3 '협업·콜라보·컬래버'(브랜드 협업 상품, 굿즈, 팝업스토어)를 광고·상업성으로 보는가 | C4: · 브랜드·기업 협업만 포함(음악 협업 제외) · 전부 제외(현행) · 보류 | D4: '협업'은 미매칭 근접 어휘 1위(154건)지만 대부분 음악 협업(피처링)이다. 브랜드 협업만 넣으려면 '브랜드/기업/제품 + 협업' 같은 조건부 규칙이 필요하다. | E4: 브랜드·기업 협업만 포함 — 단, 조건부 규칙이라 오탐 검수 필요
A5: 광고 | B5: Q4 광고 지수 재산출 시 원본 JSON(ad_commercial_index_v7.json)을 교체하는가, 병행 파일로 두는가 | C5: · 병행 파일(v7_1)로 두고 README 표는 병기 · 원본 교체(verify 항목 갱신) · 보류 | D5: 원본 교체는 verify 107항목·README 6절·기술명세 수치가 함께 바뀐다. 병행은 두 판이 공존한다. | E5: 병행 파일 — 최종 보고서 PDF 수치와의 대응을 유지
A6: 미디어 | B6: Q5 라디오(라디오 DJ·출연·진행)를 미디어·콘텐츠 노출로 보는가 | C6: · 포함(서브태그 '라디오' 신설) · 제외(현행: 예능/유튜브/영화/드라마만) · 보류 | D6: 표본 17건 중 2건, 미매칭 근접 어휘 47건. 서브태그를 하나 늘리면 지수 정의(4종)가 5종이 된다. | E6: 포함 — 방송 매체 노출이라는 지수 취지와 같음
A7: 미디어 | B7: Q6 서브태그 단어 없이 프로그램명만 나오는 예능·서바이벌(런닝맨·아는 형님·나는 가수다·쇼미더머니·히든싱어·미스터트롯 …)을 어떻게 잡는가 | C7: · 프로그램명 목록을 사전에 추가(목록 유지 필요) · '출연/MC/심사위원/우승' + 방송사(KBS/MBC/SBS/JTBC/tvN/Mnet) 조합 규칙 · 둘 다 · 현행 유지(안 잡음) | D7: 표본 누락 17건 중 11건이 이 유형. 재현율 0.57의 주원인. 목록은 정확하지만 새 프로그램마다 갱신해야 하고, 조합 규칙은 갱신이 없지만 오탐(뉴스 보도 문장)이 생긴다. | E7: 둘 다 — 목록으로 정확도, 규칙으로 갱신 부담 완화
A8: 미디어 | B8: Q7 영문·일문 방송 표현(documentary, variety show, singing-competition show, late show, バラエティ番組)을 넣는가 | C8: · 넣는다 · 넣지 않는다 · 보류 | D8: 표본 4건. 광고 Q1과 같은 성격(언어만 다름). | E8: 넣는다
A9: 미디어 | B9: Q8 OTT·웹예능·웹드라마·뮤지컬·연극·팟캐스트를 미디어 노출로 보는가 | C9: · OTT·웹예능·웹드라마 포함, 뮤지컬·연극·팟캐스트 제외 · 전부 포함 · 전부 제외(현행) | D9: OTT 드라마는 '드라마'로 이미 잡히는 경우가 많다. 뮤지컬·연극은 공연(F3 현장경제)에 가깝다. | E9: OTT·웹예능·웹드라마 포함, 뮤지컬·연극·팟캐스트 제외
A10: 지역 | B10: Q9 영문 지명(Seoul, Incheon, Daegu, Busan, Uijeongbu …)을 국내 지역 언급으로 보는가 | C10: · 넣는다(17개 시·도 + 주요 도시 영문 표기) · 넣지 않는다 · 보류 | D10: 표본 6건 중 3건. 영문 불릿의 국내 투어 기사가 잡힌다. | E10: 넣는다
A11: 지역 | B11: Q10 사전 밖 군 단위(봉화·철원·해남 …)와 도 전체명(경상북도·전라남도 …)을 넣는가 | C11: · 행정구역 전체 목록(시·군·구 + 도 전체명)으로 교체 · 표본에서 나온 것만 추가 · 현행 유지 | D11: 전체 목록은 동음 지명(광주·고성·경주·전주·진주·화성 …)이 늘어 L17의 배제 규칙을 함께 넓혀야 한다. | E11: 표본에서 나온 것만 추가 + 도 전체명 — 동음 확대를 피함
A12: 지역 | B12: Q11 대학·경기장·시설명(고려대·잠실·올림픽공원·KSPO돔 …)으로 지역을 유추하는가 | C12: · 유추하지 않는다(현행) · 주요 시설 → 지역 매핑표를 둔다 · 보류 | D12: 시설 매핑은 정확하지만 표를 만들어야 하고 '서울' 편중이 더 커진다. | E12: 유추하지 않는다
A13: 공통 | B13: Q12 재산출 결과를 어디까지 반영하는가 | C13: · 지수 JSON/CSV 병행 파일만 · 병행 파일 + README 6절 표 병기 · 원본 교체 + README·verify 갱신 | D13: README 6절의 광고 1,302·미디어 1,025 같은 수치와 검증 107항목이 걸려 있다. | E13: 병행 파일 + README 6절 표 병기

Sheet 광고
A1: 번호 | B1: 팬덤 | C1: 유형 | D1: 문장 | E1: 힌트어(사전 밖 유사 표현) | F1: 모델 판독(Y/N) | G1: 판독 사유 | H1: 저자 판정(A∼E) | I1: 추가할 표현(A일 때, 문장에 나온 말 그대로) | J1: 집계 대상(A일 때: 지역=시·도, 미디어=서브태그) | K1: 메모
A2: 1 | B2: (여자)아이들 | C2: loyalty | D2: (여자)아이들의 네 번째 월드투어 'Syncopation' 마카오 공연 추가 회차는 2026년 예매 시작 직후 매진됐다. | F2: N | J2: (해당 없음)
A3: 2 | B3: 프로미스나인 | C3: loyalty | D3: 프로미스나인의 플레디스 계약 종료(결별) 소식이 YesAsia.ru에 보도됨 | F3: N | J3: (해당 없음)
A4: 3 | B4: 임영웅 | C4: spillover | D4: 임영웅, SBS와 손잡고 예능 복귀…컴백 효과 극대화 노리는 전략 보도 | F4: N | J4: (해당 없음)
A5: 4 | B5: BTS | C5: loyalty | D5: 월드투어 'ARIRANG'으로 브라질에서 3회 공연을 개최하며 티켓 판매 소식이 브라질 매체에 대대적으로 보도됨 | F5: N | J5: (해당 없음)
A6: 5 | B6: 박서진 | C6: loyalty | D6: 산불 기부로 닻별의 누적 기부액은 1억 2,800만 원을 기록하며 '착한팬클럽 골드' 등급을 재확인했다. | F6: N | J6: (해당 없음)
A7: 6 | B7: Hearts2Hearts | C7: spillover | D7: 2025년 각종 시상식에서 신인상을 7회 수상했다. | F7: N | J7: (해당 없음)
A8: 7 | B8: ITZY | C8: spillover | D8: 멕시코 매체 Bitácora CDMX가 있지가 2024년 4월 15일 멕시코시티 페시 센터 WTC에서 'BORN TO BE' 월드투어 공연을 연다고 보도했다. | F8: N | J8: (해당 없음)
A9: 8 | B9: 동방신기 | C9: spillover | D9: 스페인 기반 케이팝 블로그 '바나나(BA NA NA)'가 동방신기의 컴백곡 'Love Line' 뮤직비디오를 리뷰하며, SM엔터테인먼트가 영상 속 세계지도에서 일본이 누락된 사실이 팬들에게 발견된 뒤 영상을 일시적으로 내렸다고 전했다. | F9: N | J9: (해당 없음)
A10: 9 | B10: 마마무 | C10: spillover | D10: MAMAMOO announced their 2026 "4WARD" world tour — 13 stops including Seoul (June 19-21), marking their first group comeback/tour in about 4 years, tied to their 12th debut anniversary. | F10: N | J10: (해당 없음)
A11: 10 | B11: NewJeans | C11: loyalty | D11: ADOR extended all Bunnies fan club memberships by 365 days automatically on March 25, 2026, framed as "appreciation for continued support" amid ongoing legal disputes involving member Danielle - fan reaction was mixed, with many demanding clarity on her status | F11: N | J11: (해당 없음)
A12: 11 | B12: 빅마마 | C12: loyalty | D12: 멤버 이영현·신연아·이지영·박민혜는 2021년 6월 디지털 싱글로 9년 만에 완전체로 재결합했다. | F12: N | J12: (해당 없음)
A13: 12 | B13: GOT7 | C13: spillover | D13: 진영은 2019년 tvN 드라마 'He Is Psychometric'으로 첫 주연을 맡은 이후 'Yumi's Cells', 'The Witch', 'Our Unwritten Seoul' 등 다수의 드라마에서 연이어 주연을 맡으며 배우로서 입지를 다졌다. | F13: N | J13: (해당 없음)
... A39: 38 | B39: 워너원 | C39: spillover | D39: 워너원 출신 라이관린, 연기자 됐다···중국 드라마 출연. 그룹 '워너원' 출신 라이관린(18)이 연기 활동을 병행한다. 소속사 큐브 엔터테인먼트에 따르면 라이관린은 중국 드라마 '초연나건소사(初戀那件小事)' 출연을 확정했다. | F39: N | J39: (해당 없음)
A40: 39 | B40: DAY6 | C40: spillover | D40: DAY6 was named the new brand ambassador for British sports brand Umbro's "STAND BY ME" campaign (Feb 4, 2025), with a co-created HBL apparel collection sold at Umbro stores nationwide and online | F40: Y | G40: brand ambassador / campaign (영문) | J40: (해당 없음)
A41: 40 | B41: 윤도현 | C41: loyalty | D41: YB 명의로 2025년 2월 EP 'Odyssey'와 싱글 'Rebellion(feat. Xdinary Heroes)'을 연이어 발매하며 세대를 넘나드는 협업으로 팬덤과의 접점을 이어감 | E41: 협업 | F41: N | J41: (해당 없음)
A42: 41 | B42: ATEEZ | C42: loyalty | D42: 2026년 3월 마닐라 콘서트를 '판타지'로 표현하며 팬들과 공유했다고 현지 매체가 보도 | F42: N | J42: (해당 없음)
A43: 42 | B43: 장윤정 | C43: loyalty | D43: 위 콘서트 현장 기사에서 퇴장하는 관객들이 '돈이 아깝지 않다', '정말 재밌다'는 반응을 보였고 공연 후 포토존에 긴 대기 줄이 이어졌다고 전했다. | F43: N | J43: (해당 없음)
A44: 43 | B44: 린 | C44: spillover | D44: "Back in Time" (2012) reached #1 on the weekly Gaon Digital Chart and sold over 3 million copies; "LOVE" (2018) sold 6,536,156 downloads; "My Destiny" (2013, My Love from the Star OST) sold 1,074,581 downloads and won Best OST at the 50th Baeksang Arts Awards (2014) — noted as the first artist to win that category | F44: N | J44: (해당 없음)
A45: 44 | B45: 다비치 | C45: loyalty | D45: "Just the Two of Us"가 2013년 3월 엠카운트다운을 포함해 통산 15번째 음악방송 1위를 달성했다 | F45: N | J45: (해당 없음)
A46: 45 | B46: 브라운아이즈 | C46: spillover | D46: 2001년 제3회 엠넷 뮤직비디오 페스티벌에서 '벌써 일년'으로 신인그룹상을 수상했다. | F46: N | J46: (해당 없음)
A47: 46 | B47: 10CM | C47: spillover | D47: 10CM의 1집 《1.0》은 발매 후 1주일 만에 판매량 1만 장을 돌파했다 | F47: N | J47: (해당 없음)
A48: 47 | B48: 오마이걸 | C48: loyalty | D48: WM엔터테인먼트가 오마이걸 완전체 컴백을 2026년 상반기로 연기하면서, 원래 2027년 3월 18일까지였던 공식 팬클럽 '미라클' 6기 멤버십의 활동 기간을 연장 운영하기로 결정했다고 공식 발표함 | F48: N | J48: (해당 없음)
A49: 48 | B49: HOT | C49: spillover | D49: 2025년 11월 한터 뮤직 페스티벌에서 H.O.T.는 2AM, 틴탑, 마마무 쏠라, 오마이걸, 프로미스나인, 트리플에스 등 후배 가수들과 함께 무대에 올랐다. | F49: N | J49: (해당 없음)
A50: 49 | B50: 나훈아 | C50: spillover | D50: 대만 매체 The News Lens(關鍵評論網)가 나훈아를 "당대의 가왕(歌王)", "가요계의 살아있는 전설"로 소개하는 인물 기사를 게재했다. 기사는 2003년 삼성 이건희 회장의 생일 행사 초청을 그가 거절하며 "나는 대중 가수이다. 그러므로 티켓을 구매한 관객 앞에서만 공연하겠다"고 말한 일화를 전했다. | F50: N | J50: (해당 없음)
A51: 50 | B51: 샤이니 | C51: loyalty | D51: WOWOW가 SHINee 일본 데뷔 15주년 및 일본 공연 독점 생중계를 특집으로 편성했다는 보도 | F51: N | J51: (해당 없음)
A52: 51 | B52: 김재중 | C52: loyalty | D52: 2026년 8월 29~30일 서울 KBS아레나에서 열린 단독 콘서트 '2026 KIM JAE JOONG CONCERT [THE WAVE]'는 한국에서 그의 첫 스탠딩 공연 형태로 진행됐으며, 앙코르에서는 2006년 발표곡 'To the Boy'를 국내 최초로 라이브 공연해 팬들이 처음부터 끝까지 적극적으로 호응했다. | F52: N | J52: (해당 없음)
A53: 52 | B53: 워너원 | C53: loyalty | D53: 2026년 1월~4월, 해체 7년 만에 Mnet 리얼리티쇼 "워너원 고: 백 투 베이스"를 통해 재결합을 성사시켰으며, 팬들을 향한 자필 편지 공개 등으로 팬덤 재결집을 이끌었다 | F53: N | J53: (해당 없음)
... A74: 73 | B74: HOT | C74: spillover | D74: H.O.T. 인기로 인해 교육부가 사상 세 차례 전국 조퇴금지령을 발령했고, 2018년 재결합 콘서트 때는 관련 SRT 이용객 수가 최고치를 경신함 | F74: N | J74: (해당 없음)
A75: 74 | B75: 최예나 | C75: spillover | D75: 스페인 K팝 매체 바나나(BA NA NA)가 최예나가 비비와 협업한 'SMiLEY'로 솔로 데뷔했다고 보도했다. | E75: 협업 | F75: N | J75: (해당 없음)
A76: 75 | B76: Zion.T | C76: spillover | D76: 이문세와 협업한 '눈(Snow)'(2017)은 국내 주요 음악 차트를 모두 석권했다 | E76: 협업 | F76: N | J76: (해당 없음)
A77: 76 | B77: 임영웅 | C77: loyalty | D77: 임영웅 팬클럽 '영웅시대'는 2025년 8월 앨범 구입비 300만 원을 성금으로 기부했다. | F77: N | J77: (해당 없음)
A78: 77 | B78: 나훈아 | C78: spillover | D78: 나훈아는 1972년 12월 백마부대에서 명예 대위 직함을 받고, 파월 장병을 위한 위문공연을 위해 베트남으로 출국하는 등 국방부·군 관련 명예직을 통한 위문 활동을 했다. | F78: N | J78: (해당 없음)
A79: 78 | B79: TWICE | C79: loyalty | D79: 태국 매체 Thairath는 TWICE의 5번째 월드투어 'READY TO BE' 방콕 공연(2023년 9월 23~24일, 임팩트 아레나 무앙통타니, 라이브네이션 주최)을 "4년 만의 귀환"으로 소개하며 팬들에게 워밍업을 당부했다 | F79: N | J79: (해당 없음)
A80: 79 | B80: 몬스타엑스 | C80: spillover | D80: "SPOTLIGHT" 발매 당일 오리콘 랭킹 2위, 이튿날 8,150장 추가 판매로 1위에 등극해 일본 내 인기를 보여준 사례로 소개됐다. | F80: N | J80: (해당 없음)
A81: 80 | B81: Stray Kids | C81: loyalty | D81: 2023년 앨범 '5-Star'는 선주문 513만장을 기록하며 K팝 그룹 최초로 앨범 선주문 500만장을 돌파했고, 한국음악콘텐츠협회(KMCA)로부터 국내 세 번째로 '500만 앨범' 인증을 받았다. | F81: N | J81: (해당 없음)
A82: 81 | B82: 몬스타엑스 | C82: loyalty | D82: 'The Phase' 활동 인터뷰에서 기현은 "팬들이 한국어로 떼창하는 걸 들으면서 우리가 왜 계속 무대에 서야 하는지 다시 깨달았다"고 말했다. | F82: N | J82: (해당 없음)
A83: 82 | B83: 브라운아이즈 | C83: loyalty | D83: 나무위키 '팬덤/목록' 문서에 따르면 브라운아이즈의 공식 팬덤명은 'B.E(비이)'이며 공식 색깔은 갈색이다. | F83: N | J83: (해당 없음)
A84: 83 | B84: 박정현 | C84: spillover | D84: '작은 거인' 박정현이 복면가왕 최초로 무대에 올랐다. | F84: N | J84: (해당 없음)
A85: 84 | B85: 프로미스나인 | C85: loyalty | D85: 2025년 1월 소속사(Asnd)를 옮기면서도 5인 멤버 전원이 완전체를 유지, 6번째 EP 'From Our 20's'(2025.6)를 발매했다. | F85: N | J85: (해당 없음)
...

Sheet 미디어
A1: 번호 | B1: 팬덤 | C1: 유형 | D1: 문장 | E1: 힌트어(사전 밖 유사 표현) | F1: 모델 판독(Y/N) | G1: 판독 사유 | H1: 저자 판정(A∼E) | I1: 추가할 표현(A일 때, 문장에 나온 말 그대로) | J1: 집계 대상(A일 때: 지역=시·도, 미디어=서브태그) | K1: 메모
A2: 1 | B2: 엔믹스 | C2: spillover | D2: 인도네시아 매체 디틱과 IDN Times는 엔믹스가 K팝 그룹 최초로 브라질 카니발 무대('Bloco Da Pabllo' 2026)에 올라 "기록을 세웠다(cetak rekor)"고 보도했다 - 팬덤 밖 남미 대중문화 시장까지 화제성이 확산된 사례다 | F2: N
A3: 2 | B3: 이영지 | C3: loyalty | D3: 월드투어 공식 굿즈(MD)를 현장 티켓 확인 절차까지 두고 사전 판매할 만큼 팬 구매 수요가 크다. | F3: N
A4: 3 | B4: 임영웅 | C4: loyalty | D4: Fan club 영웅시대 donated 200 million won (2억원) to Korea University Medical Center (Anam/Guro/Ansan hospitals) in Lim Young-woong's name on his birthday, supporting low-income patients; his own cumulative donations across causes total 2.5 billion won | F4: N
A5: 4 | B5: 마마무 | C5: spillover | D5: 칠레 매체 라콰르타(La Cuarta)는 마마무가 2014년 데뷔 이후 재즈·소울·R&B를 접목한 음악과 자체 작사·작곡 활동으로 K팝에서 여성 서사를 대표하는 그룹으로 자리매김했다고 보도했다. | F5: N
A6: 5 | B6: 샤이니 | C6: spillover | D6: 6년 만의 도쿄돔 공연에서 진주빛 아쿠아그린 응원봉으로 물든 회장이 환호로 가득 찼다고 일본 매체가 보도: "見渡す限り、グループカラーであるパールアクアグリーン色のペンライトで染められた幻想的な東京ドーム" | F6: N
A7: 6 | B7: EXO | C7: loyalty | D7: 2014년 5월 24일 'Lost Planet' 콘서트 티켓이 1.47초 만에 매진됐다. | F7: N
A8: 7 | B8: 여자친구 | C8: loyalty | D8: Natalie (natalie.mu), Japan's major music/culture news site, covered the release of GFriend's second Japanese photobook "CHOICE," a fan-merchandise item aimed at the group's dedicated Japanese fanbase. | F8: N
A9: 8 | B9: 영탁 | C9: loyalty | D9: For his 20th debut anniversary, fan club YOUNGTAK & BLUES donated ₩68.35 million to UNICEF Korea. | F9: N
A10: 9 | B10: LE SSERAFIM | C10: loyalty | D10: 2026년 5월 데뷔 4주년을 맞아 전 세계 공식 팬덤 '피어나(FEARNOT)'와 함께 'CELEBRATION' 기념 활동을 진행했다는 보도 | F10: N
A11: 10 | B11: 거미 | C11: loyalty | D11: 데뷔 20년이 지난 시점에도 히트곡들이 노래방 인기차트에 꾸준히 오르는 등 장기적인 대중적 스트리밍/소비력을 유지하고 있다. | F11: N
A12: 11 | B12: 투어스(TWS) | C12: spillover | D12: Kapanlagi.com confirmed no Indonesian city appears on TWS's official 2026 Asia tour schedule, describing Jakarta as 'passed' and noting local fan disappointment. | F12: N
A13: 12 | B13: 나훈아 | C13: spillover | D13: 2025.1 전국투어 은퇴 콘서트 '고마웠습니다' 최종 마무리, 58년 가수 인생에 마침표 | F13: N
A14: 13 | B14: 최예나 | C14: loyalty | D14: 최예나는 2024년 팬콘서트 'SUPER YENA'부터 2026년 라이브투어 '잡힐 듯 말 듯 한, 2세계!'까지 꾸준히 단독 공연을 이어가며 팬덤과의 접점을 확대하고 있다 | F14: N
A15: 14 | B15: 지코 | C15: spillover | D15: '쇼미더머니' 시리즈 4·6·12편 등 여러 시즌에 프로듀서로 참여하며 힙합 신 전반에 영향력을 확장했다. | F15: Y | G15: 예능 프로그램명 '쇼미더머니' 프로듀서 참여
A16: 15 | B16: TWICE | C16: spillover | D16: 한국 여성 아티스트 최초로 빌보드 월드앨범차트와 월드디지털송세일즈차트를 동시 석권했다. | F16: N
A17: 16 | B17: LE SSERAFIM | C17: spillover | D17: 르세라핌, 2023년 10월 루이비통(Louis Vuitton) 하우스 앰버서더로 발탁 | F17: N
A18: 17 | B18: EXO | C18: spillover | D18: 3년 만의 컴백 앨범 'REVERXE' 소식을 빌보드 브라질이 상세 보도 | F18: N
A19: 18 | B19: 이영지 | C19: spillover | D19: 나타리 뮤직에 이영지 아티스트 프로필 페이지가 개설되어 있다 | F19: N
A20: 19 | B20: 박효신 | C20: spillover | D20: 중국어 위키백과(维基百科) 박효신 항목에 그가 일본 가수 나카시마 미카(中島美嘉)의 대표곡 '유키노하나'(雪の花, 눈의 꽃)를 커버한 사실이 기록되어 있어, 중화권 정보원에서도 그의 레퍼토리가 일본 음악과 맞닿아 있음이 소개되고 있다. | F20: N
A21: 20 | B21: 지코 | C21: loyalty | D21: 2015년 멜론 라디오 프로그램 진행 | E21: 라디오 | F21: Y | G21: 라디오 프로그램 진행
A22: 21 | B22: 이영지 | C22: spillover | D22: 2024년 6월 발매한 첫 정규 앨범 '16 Fantasy'가 멜론 데일리 차트 1위, 위클리 차트 3주 연속 2위를 기록했다 | F22: N
A23: 22 | B23: 박서진 | C23: loyalty | D23: 2022년 10월 대전 뮤직페스티벌에서 닻별 회원들은 비가 내리는 와중에도 관객을 위해 좌석을 닦고 공연 후 쓰레기를 치우는 현장 봉사를 했다. | F23: N
A24: 23 | B24: 잭스키스 | C24: spillover | D24: Documentary "Sechskies Eighteen" (2018) ranked #1 in Korean seat sales for February 2018, selling 91.4% of available seats and topping 50,000 tickets sold by March 2018. | F24: Y | G24: Documentary (영문 다큐·영화)
A25: 24 | B25: 거미 | C25: spillover | D25: 거미는 MBC '나는 가수다' 시즌1(2011)에 출연자로 참여했다. | F25: Y | G25: MBC '나는 가수다' 출연
A26: 25 | B26: 비비 | C26: spillover | D26: 남서울대학교 축제 공연에서 비비의 비속어 발언에 현장 관객은 즉각 호응했지만, 온라인에서는 '수천만원 학비로 가수 불렀더니 학교를 깎아내렸다'는 등 부정적 반응이 대부분이었고 관련 영상은 59만 조회수를 기록했다. | F26: N
A27: 26 | B27: 백지영 | C27: spillover | D27: 백지영은 2013년 5월 일본에서 첫 단독 콘서트를 매진시켰다. | F27: N
A28: 27 | B28: 동방신기 | C28: loyalty | D28: TVXQ held "2023 TVXQ CONCERT '20&2'" (Dec. 30-31, 2023) marking 20 years since debut and their first concert in ~4 years 9 months; fandom Cassiopeia described as "800,000-strong". | F28: N
A29: 28 | B29: Stray Kids | C29: spillover | D29: 2026년 5월 기준 한국·일본 앨범 합산 누적 판매량이 4천만 장을 넘어섰다 | F29: N
A30: 29 | B30: 케이윌 | C30: spillover | D30: Set a record of five consecutive wins on Immortal Songs 2 before departing in January 2012, and appeared as a "Master" on the singing-competition show Tomorrow's National Singer (August 2021) | F30: Y | G30: Immortal Songs 2 / singing-competition show (영문 예능)
A31: 30 | B31: 보아 | C31: loyalty | D31: BoA established a new fan club "Jumping BoA 1기" after leaving SM Entertainment in 2026 and founding her own agency BApal Entertainment; recruitment ran from the 1st to the 17th (2026), as the first artist on fandom platform PLEDGE by day1dream | F31: N
A32: 31 | B32: STAYC | C32: spillover | D32: 넥슨이 온라인 액션 RPG '엘소드(Elsword)'의 공식 홍보 모델로 걸그룹 STAYC를 발탁하고 신곡 'Bubble' 콘셉트의 협업 콘텐츠를 선보였다(2023년 8월 17일). | F32: N
A33: 32 | B33: (여자)아이들 | C33: spillover | D33: 홍콩 HK01은 (여자)아이들의 곡 "Wife"에 대해 "含大量性暗示「歌詞中文意思曝光」直逼19禁"라는 제목으로 가사 중문 번역과 함께 선정성 논란을 보도했다. | F33: N
A34: 33 | B34: 나훈아 | C34: loyalty | D34: His 2024 "고마웠습니다 - 라스트 콘서트" (farewell tour) sold out virtually instantly, triggering a wave of scalping activity. | F34: N
A35: 34 | B35: 박재범 | C35: spillover | D35: 원소주 팝업스토어는 열릴 때마다 전량 매진되는 등 오프라인 유통에서도 화제를 모았다. | F35: N
A36: 35 | B36: SEVENTEEN | C36: spillover | D36: 세븐틴이 2015년 SBS '런닝맨', 2019년 JTBC '아는 형님'에 출연했다. | F36: Y | G36: SBS '런닝맨', JTBC '아는 형님' 출연
A37: 36 | B37: BABYMONSTER | C37: spillover | D37: 튀르키예 방송사 TGRT Haber는 BABYMONSTER를 'YENİ BLACKPINK(새로운 블랙핑크)'로 소개하며 멤버 국적과 나이, 데뷔곡 'Batter Up' 발매 소식을 전했다. | F37: N
A38: 37 | B38: 아이유 | C38: spillover | D38: 구찌(GUCCI)가 2022년 아이유를 글로벌 앰버서더로 발탁한 데 이어, 2024년 2월 마리끌레르 코리아와 함께한 '비욘드 장르(Beyond Genre)' 화보를 통해 2024년에도 구찌 캠페인 모델 활동을 이어갔다. | F38: N
A39: 38 | B39: BTS | C39: loyalty | D39: BARKS가 BTS의 뉴욕 그랜드 센트럴역 'ON' 깜짝 무대 소식을 팬 반응과 함께 보도했다 | F39: N
A40: 39 | B40: 최예나 | C40: spillover | D40: 최예나, 신곡 제목 'Hate Rodrigo'가 올리비아 로드리고 겨냥한 것 아니냐는 논란 | F40: N
...

Sheet 지역
A1: 번호 | B1: 팬덤 | C1: 유형 | D1: 문장 | E1: 힌트어(사전 밖 유사 표현) | F1: 모델 판독(Y/N) | G1: 판독 사유 | H1: 저자 판정(A∼E) | I1: 추가할 표현(A일 때, 문장에 나온 말 그대로) | J1: 집계 대상(A일 때: 지역=시·도, 미디어=서브태그) | K1: 메모
A2: 1 | B2: aespa | C2: loyalty | D2: 데뷔 EP 'Savage'(2021)가 누적 78만 8,959장 팔리며 2023년 5월까지 SM 소속 그룹 데뷔 음반 최고 판매 기록을 유지했다 | F2: N
A3: 2 | B3: 조용필 | C3: spillover | D3: 갤럽코리아 선정 2013년 '올해의 가수'로 뽑혔고 은관문화훈장을 받았다 | F3: N
A4: 3 | B4: RIIZE | C4: spillover | D4: RIIZE became the new brand ambassador for Crocs Japan | F4: N
A5: 4 | B5: 박서진 | C5: loyalty | D5: 박서진은 2025년 하반기 '뉴트렌드 대상' 예선에서 음악 부문 35.15%, 멀티테이너 부문 62.88% 득표율로 각각 1위에 올랐으며, 멀티테이너 부문에서는 블랙핑크 지수(11.73%)를 앞섰다. | F5: N
A6: 5 | B6: LE SSERAFIM | C6: loyalty | D6: 'Easy'로 그룹 최초 빌보드 핫100에 진입했다. | F6: N
A7: 6 | B7: 레드벨벳 | C7: loyalty | D7: 'SMTOWN LIVE 2025 in MEXICO CITY'(2025년 5월 9일, Estadio GNP Seguros) 최종 라인업에 레드벨벳(웬디·예리 제외)이 포함되었다고 확정 보도. | F7: N
A8: 7 | B8: IVE | C8: spillover | D8: 아이브 리즈가 JTBC 주말드라마 '천국보다 아름다운'(김혜자·손석구 주연)의 다섯 번째 OST 트랙 'Heavy Love'를 2026년 5월 18일 발매했다. 웅장한 현악 사운드와 리즈 특유의 맑고 강한 보컬톤으로 사랑의 본질을 표현했다는 평을 받았다. | F8: N
A9: 8 | B9: sg워너비 | C9: spillover | D9: SG워너비 멤버 채동하는 2007년 KBS 드라마 '인순이는 예쁘다' OST에 솔로곡 '언제까지나'로 참여했다. | F9: N
A10: 9 | B10: 박재범 | C10: loyalty | D10: 박재범(Jay Park)의 모스크바 콘서트 홍보 페이지가 러시아 콘서트 기획사 Bright Side Concerts에 개설됨 | F10: N
A11: 10 | B11: 이영지 | C11: loyalty | D11: 2026년 2월 모바일 게임 '경찰과 도둑'을 통해 팬들과 함께 아동병원에 3억 원을 기부하는 캠페인을 진행, 팬덤과의 협업형 선행이 이루어졌다 | F11: N
A12: 11 | B12: 케이윌 | C12: spillover | D12: "러브 119", "이러지마 제발" 등 다수의 음원 1위 곡을 보유해 '음원 킹'으로 불리며 장기간 스트리밍 시장에서 영향력을 발휘해왔다. | F12: N
A13: 12 | B13: 동방신기 | C13: loyalty | D13: 'Time' 투어(2013)가 85만 관객을 동원하며 9000만달러의 매출을 올렸다. | F13: N
... A43: 42 | B43: 소녀시대 | C43: loyalty | D43: "在少女時代演唱會時也給予了很多帥氣的應援活動" — 태연 인터뷰 기사에서 SONE(팬덤)이 콘서트에서 보여준 응원 활동을 "센스있다(SONE非常有Sense)"고 평가 | F43: N
A44: 43 | B44: 송가인 | C44: spillover | D44: 송가인이 경상북도 봉화군 내성천 체육공원에서 열린 제29회 봉화송이축제 폐막식(2025년 10월 19일)에 출연해 가을밤 무대를 장식했다. | F44: Y | G44: 경상북도 봉화군 — '경북' 약칭만 사전, 봉화 없음
A45: 44 | B45: 싸이 | C45: loyalty | D45: 태국 mgronline.com은 싸이가 말춤을 선보이며 태국 팬들의 지지에 감사를 표하고 재방문 의사를 밝힌 현장을 보도했다 | F45: N
A46: 45 | B46: 여자친구 | C46: loyalty | D46: Natalie (natalie.mu), Japan's major music/culture news site, covered the release of GFriend's second Japanese photobook "CHOICE," a fan-merchandise item aimed at the group's dedicated Japanese fanbase. | F46: N
A47: 46 | B47: 박재범 | C47: loyalty | D47: Jay Park 팬미트 파티 티켓 9월7일 판매 개시 | F47: N
A48: 47 | B48: 에픽하이 | C48: spillover | D48: 리더 타블로가 CNN 브라질과 인터뷰하며 케이팝 아이돌들의 참고 대상이 되는 소감을 밝힘 | F48: N
A49: 48 | B49: 권은비 | C49: spillover | D49: Sang her first drama OST, a remake of Lee Seung-hwan's "세상에 뿌려진 사랑만큼," marking a "OST 퀸" crossover moment beyond music/festival work | F49: N
A50: 49 | B50: 슈퍼주니어 | C50: spillover | D50: 슈퍼주니어 최시원은 2024년 드라마 'DNA러버'에서 심연우 역 주연을 맡았고 영화 '동화지만 청불입니다'(정석 역), '로비'(마태수 역)에도 출연했으며, 현재 유니세프 한국위원회 특별대표와 마약퇴치운동본부 고문으로 활동 중이다. | F50: N
A51: 50 | B51: 싸이 | C51: spillover | D51: 하이트진로가 2012년 11월 싸이를 소주 '참이슬'과 맥주 '드라이피니시d' 광고 모델로 동시에 발탁해, 한 모델이 소주와 맥주 광고를 함께 맡는 업계의 이례적인 계약을 성사시켰다. | F51: N
A52: 51 | B52: 투어스(TWS) | C52: loyalty | D52: TWS held their first official fan meeting, '42:Club' in Seoul, February 14–16, 2025 at Seoul Olympic Park's Handball Gymnasium; advance reservations for all three sessions sold out at high speed. | F52: Y | G52: Seoul Olympic Park (영문 지명)
A53: 52 | B53: CORTIS | C53: loyalty | D53: 2번째 EP 'GreenGreen'은 초동 판매량 약 231만 장을 기록해 데뷔작 대비 약 5배 성장했으며, 빌보드 200 3위에 진입했다. | F53: N
A54: 53 | B54: 린 | C54: spillover | D54: 린은 2024년 11월부터 2025년 2월까지 방영된 '현역가왕2'에서 심사위원으로 활동했다. | F54: N
A55: 54 | B55: BLACKPINK | C55: spillover | D55: 페루 매체 La República가 블랙핑크가 2023년 4월 26~27일 멕시코시티 포로 솔에서 공연하며 한국 걸그룹 최고 흥행 투어 기록을 세웠다고 보도했다. | F55: N
A56: 55 | B56: 엔믹스 | C56: spillover | D56: 2025년 패션 브랜드 게스(GUESS)의 아시아 앰버서더로 멤버 전원이 계약을 맺었다. | F56: N
A57: 56 | B57: 아이유 | C57: spillover | D57: 아이유가 2026년 9월 4일 0시 공식 SNS를 통해 새 디지털 싱글의 레트로 콘셉트 티저 영상을 공개했고, 9월 10일 오후 6시 발매 예정이라는 소식이 다수 매체를 통해 보도되었다. | F57: N
A58: 57 | B58: 이찬원 | C58: loyalty | D58: Lee Chan-won personally donated 100 million won to the Love of Sharing Social Welfare Community Chest on Nov 29, 2024, becoming an Honor Society member (100M+ won donor club), explicitly citing his fan club's charitable activity as his motivation ("to add warmth to match the club's good deeds") | F58: N
A59: 58 | B59: 오마이걸 | C59: spillover | D59: Japan debut album sold 9,383 physical copies on Oricon Daily, 15,910 units on the Oricon Weekly Chart, and 20,041 units on Billboard Japan Top Albums Sales | F59: N
A60: 59 | B60: DAY6 | C60: loyalty | D60: 2025년 'Forever Young' 마닐라 콘서트를 마치며 '너희들 정말 대단했다'고 밝힘 | F60: N
A61: 60 | B61: 청하 | C61: spillover | D61: 청하는 2019년 tvN 드라마 '호텔 델루나' OST Part.6에 수록곡 '그 끝에 그대(At the End)'를 불렀으며, 이 곡은 'Hotel Del Luna OST Part.6' 싱글로 Spotify에 정식 등재되어 있다. | F61: N
A62: 61 | B62: NCT | C62: loyalty | D62: 중국 포털 360엔터(360娱乐)에 웨이신V(威神V, WayV) 멤버 샤오쥔(肖德俊, Xiaojun)이 한국 SBS M 음악방송 《THE SHOW》의 새 MC로 발탁됐다는 소식이 실렸고, 웨이보 해시태그 "#肖俊将担任THESHOWMC#"(샤오쥔, THE SHOW MC 맡는다)가 화제가 되어 팬들이 "祝贺肖俊"(샤오쥔 축하해), "期待MC肖俊"(MC 샤오쥔 기대돼) 등의 댓글을 남겼다고 전했다. | F62: N
A63: 62 | B63: 최예나 | C63: loyalty | D63: 인도네시아 K팝 매체 kpopchart.net이 최예나의 4집 미니앨범 'Blooming Wings'(2025.7.29 발매) 컴백과 연계해 도쿄·오사카 콘서트 소식을 전하며 팬들과의 교감을 강화하는 인터랙티브 이벤트를 예고함. | F63: N
A64: 63 | B64: IVE | C64: spillover | D64: IVE 안유진·장원영이 유닛 '안녕즈'로 2025년 1월 15일 tvN '유 퀴즈 온 더 블럭'에 출연했다. | F64: N
... A69: 68 | B69: 임영웅 | C69: loyalty | D69: 팬카페 '영웅시대' 공식 회원수가 21만 명을 달성했다. | F69: N
A70: 69 | B70: 리센느(RESCENE) | C70: spillover | D70: 철원 다슬기축제 현장에서 당시는 다소 생소한 그룹이었음에도 관객들이 뜨겁게 호응하며 앙코르 무대까지 이끌어냈고, 현재는 축제에 섭외하기도 힘들 만큼 인기 스타가 됐다는 대비를 전한 기사(네티즌 반응 인용 포함). | F70: Y | G70: 철원(강원) 다슬기축제 — 철원 없음
A71: 70 | B71: A-pink | C71: spillover | D71: 에이핑크 박초롱은 웹시리즈 '종합광고대행사: 찌찌' 시즌2 '광고의 온도' 편에 찌찌팀을 조율하는 중심인물 '민주' 역으로 합류하며, 2026년 하반기 주요 OTT 플랫폼 공개를 앞두고 있다. | F71: N
A72: 71 | B72: NewJeans | C72: spillover | D72: NewJeans는 2023년 1월 NME의 'Big Read' 커버 인터뷰를 장식했으며, 앞서 NME의 '2023년 주목할 신인 아티스트 100' 명단에도 이름을 올렸다. | F72: N
A73: 72 | B73: 거미 | C73: spillover | D73: 거미는 2015년 JTBC '히든싱어4'에 원조 가수로 출연해 우승을 차지했다. | F73: N
...

Sheet 사전후보
A1: 지표 | B1: 후보 표현(|로 구분) | C1: 근거 | D1: 표본에서 본 건수 | E1: 관련 정의결정 | F1: 처리 | G1: 수정안(수정해서 추가일 때) | H1: 메모
A2: 광고 | B2: brand ambassador|ambassador|endorsement|endorsements|brand model|spokesmodel|promotional face|campaign face | C2: 영문 불릿의 상업 계약 신호 — 표본 7건 중 6건 | D2: 6 | E2: Q1
A3: 광고 | B3: 화보 공개|브랜드 화보 | C3: '화보 촬영'만 있어 '화보 공개'를 놓침 | D3: 1 | E3: Q2
A4: 미디어 | B4: 런닝맨|아는 형님|나는 가수다|나는가수다|쇼미더머니|히든싱어|미스터트롯|더 팬|아이돌학교|겟잇뷰티|불후의 명곡|유 퀴즈|복면가왕|주간아이돌|킹덤 | C4: 예능·서바이벌 프로그램명(서브태그 단어 없이 등장) | D4: 11 | E4: Q6
A5: 미디어 | B5: 라디오|Inter-FM|FM4U|파워FM | C5: 라디오 출연·진행 | D5: 2 | E5: Q5
A6: 미디어 | B6: 서바이벌|경연|오디션 프로그램|MC|진행자|심사위원 | C6: 예능 형식어 | D6: 3 | E6: Q6
A7: 미디어 | B7: documentary|show|variety|バラエティ|番組|late show | C7: 영문·일문 방송 표현 | D7: 4 | E7: Q7
A8: 미디어 | B8: 방송 출연|특집 방송|시청률|V LIVE|브이라이브 | C8: 방송 노출 일반어 | D8: 3 | E8: Q6
A9: 지역 | B9: Seoul|Incheon|Daegu|Busan|Gwangju|Daejeon|Ulsan|Uijeongbu|Suwon|Jeju|Gyeonggi|Gangwon | C9: 영문 지명 — 표본 6건 중 3건 | D9: 3 | E9: Q9
A10: 지역 | B10: 봉화|철원|해남|명량|경상북도|경상남도|전라북도|충청남도|충청북도|강원도|경기도 광주 | C10: 사전 밖 군 단위·도 전체명 | D10: 3 | E10: Q10

Sheet 집계
A1: 지표 | B1: 표본 | C1: 모델 Y | D1: A 누락·사전추가 | E1: B 누락·사전제외 | F1: C 경계 | G1: D 아님 | H1: E 보류 | I1: 미판정 | J1: 확정 누락(A+B) | K1: 표본 누락 비율 | L1: 경계 포함 시 비율 | M1: 매칭 | N1: 미매칭 | O1: 재현율 추정 | P1: 경계 포함 시 재현율
A2: 광고 | B2: 200 | C2: =COUNTIF('광고'!F2:F201,"Y") | D2: =COUNTIF('광고'!H2:H201,"A 누락·사전추가") | E2: =COUNTIF('광고'!H2:H201,"B 누락·사전제외") | F2: =COUNTIF('광고'!H2:H201,"C 경계·정의결정") | G2: =COUNTIF('광고'!H2:H201,"D 아님") | H2: =COUNTIF('광고'!H2:H201,"E 보류") | I2: =200-SUM(D2:H2) | J2: =D2+E2 | K2: =J2/B2 | L2: =(J2+F2)/B2 | M2: 1308 | N2: 8712 | O2: =M2/(M2+N2*K2) | P2: =M2/(M2+N2*L2)
A3: 미디어 | B3: 200 | C3: =COUNTIF('미디어'!F2:F201,"Y") | D3: =COUNTIF('미디어'!H2:H201,"A 누락·사전추가") | E3: =COUNTIF('미디어'!H2:H201,"B 누락·사전제외") | F3: =COUNTIF('미디어'!H2:H201,"C 경계·정의결정") | G3: =COUNTIF('미디어'!H2:H201,"D 아님") | H3: =COUNTIF('미디어'!H2:H201,"E 보류") | I3: =200-SUM(D3:H3) | J3: =D3+E3 | K3: =J3/B3 | L3: =(J3+F3)/B3 | M3: 1025 | N3: 8995 | O3: =M3/(M3+N3*K3) | P3: =M3/(M3+N3*L3)
A4: 지역 | B4: 200 | C4: =COUNTIF('지역'!F2:F201,"Y") | D4: =COUNTIF('지역'!H2:H201,"A 누락·사전추가") | E4: =COUNTIF('지역'!H2:H201,"B 누락·사전제외") | F4: =COUNTIF('지역'!H2:H201,"C 경계·정의결정") | G4: =COUNTIF('지역'!H2:H201,"D 아님") | H4: =COUNTIF('지역'!H2:H201,"E 보류") | I4: =200-SUM(D4:H4) | J4: =D4+E4 | K4: =J4/B4 | L4: =(J4+F4)/B4 | M4: 940 | N4: 9080 | O4: =M4/(M4+N4*K4) | P4: =M4/(M4+N4*L4)
A6: 확정 누락 = A + B. C(경계)는 정의결정에서 '포함'을 고른 경우에만 누락으로 세며, 그 상한이 '경계 포함 시' 열이다. E·미판정은 누락 아님으로 계산된다. 재현율 = 매칭 / (매칭 + 미매칭 × 표본 누락 비율).
